<?xml version="1.0" ?>
﻿<sdf version='1.6'>
  <world name='default'>
    <light name='sun' type='directional'>
      <cast_shadows>1</cast_shadows>
      <pose frame=''>0 0 10 0 -0 0</pose>
      <diffuse>0.8 0.8 0.8 1</diffuse>
      <specular>0.2 0.2 0.2 1</specular>
      <attenuation>
        <range>1000</range>
        <constant>0.9</constant>
        <linear>0.01</linear>
        <quadratic>0.001</quadratic>
      </attenuation>
      <direction>-0.5 0.1 -0.9</direction>
    </light>
    <model name='ground_plane'>
      <static>1</static>
      <link name='link'>
        <collision name='collision'>
          <geometry>
            <plane>
              <normal>0 0 1</normal>
              <size>100 100</size>
            </plane>
          </geometry>
          <surface>
            <friction>
              <ode>
                <mu>100</mu>
                <mu2>50</mu2>
              </ode>
              <torsional>
                <ode/>
              </torsional>
            </friction>
            <contact>
              <ode/>
            </contact>
            <bounce/>
          </surface>
          <max_contacts>10</max_contacts>
        </collision>
        <visual name='visual'>
          <cast_shadows>0</cast_shadows>
          <geometry>
            <plane>
              <normal>0 0 1</normal>
              <size>100 100</size>
            </plane>
          </geometry>
          <material>
            <script>
              <uri>file://media/materials/scripts/gazebo.material</uri>
              <name>Gazebo/Grey</name>
            </script>
          </material>
        </visual>
        <self_collide>0</self_collide>
        <kinematic>0</kinematic>
      </link>
    </model>
    <gravity>0 0 -9.8</gravity>
    <magnetic_field>6e-06 2.3e-05 -4.2e-05</magnetic_field>
    <atmosphere type='adiabatic'/>
    <physics name='default_physics' default='0' type='ode'>
      <max_step_size>0.001</max_step_size>
      <real_time_factor>1</real_time_factor>
      <real_time_update_rate>1000</real_time_update_rate>
    </physics>
    <scene>
      <ambient>0.4 0.4 0.4 1</ambient>
      <background>0.7 0.7 0.7 1</background>
      <shadows>1</shadows>
    </scene>
    <spherical_coordinates>
      <surface_model>EARTH_WGS84</surface_model>
      <latitude_deg>0</latitude_deg>
      <longitude_deg>0</longitude_deg>
      <elevation>0</elevation>
      <heading_deg>0</heading_deg>
    </spherical_coordinates>
    <model name='abb_irb120_3_58'>
      <link name='base_link'>
        <pose frame=''>0 0 0 0 -0 0</pose>
        <inertial>
          <pose frame=''>-0.04204 8e-05 0.07964 0 -0 0</pose>
          <mass>6.215</mass>
          <inertia>
            <ixx>0.0247272</ixx>
            <ixy>-8.0784e-05</ixy>
            <ixz>0.00130902</ixz>
            <iyy>0.0491285</iyy>
            <iyz>-8.0419e-06</iyz>
            <izz>0.0472376</izz>
          </inertia>
        </inertial>
        <collision name='base_link_collision'>
          <pose frame=''>0 0 0 0 -0 0</pose>
          <geometry>
            <mesh>
              <scale>1 1 1</scale>
              <uri>/home/udp/ros_qtc_plugin/src/abb_experimental/abb_irb120_support/meshes/irb120_3_58/collision/base_link.stl</uri>
            </mesh>
          </geometry>
          <surface>
            <contact>
              <ode/>
            </contact>
            <friction>
              <ode/>
              <torsional>
                <ode/>
              </torsional>
            </friction>
            <bounce/>
          </surface>
          <max_contacts>10</max_contacts>
        </collision>
        <visual name='base_link_visual'>
          <pose frame=''>0 0 0 0 -0 0</pose>
          <geometry>
            <mesh>
              <scale>1 1 1</scale>
              <uri>/home/udp/ros_qtc_plugin/src/abb_experimental/abb_irb120_support/meshes/irb120_3_58/visual/base_link.stl</uri>
            </mesh>
          </geometry>
          <material>
            <script>
              <name>Gazebo/Orange</name>
              <uri>file://media/materials/scripts/gazebo.material</uri>
            </script>
          </material>
        </visual>
        <gravity>0</gravity>
        <velocity_decay/>
        <self_collide>0</self_collide>
        <kinematic>0</kinematic>
      </link>
      <joint name='world-base_link-fixed' type='revolute'>
        <child>base_link</child>
        <parent>world</parent>
        <axis>
          <limit>
            <lower>0</lower>
            <upper>0</upper>
          </limit>
          <dynamics>
            <damping>0</damping>
            <friction>0</friction>
            <spring_reference>0</spring_reference>
            <spring_stiffness>0</spring_stiffness>
          </dynamics>
          <use_parent_model_frame>1</use_parent_model_frame>
          <xyz>0 0 1</xyz>
        </axis>
      </joint>
      <link name='link_1'>
        <pose frame=''>0 0 0 0 -0 0</pose>
        <inertial>
          <pose frame=''>9.8e-05 -0.00012 0.23841 0 -0 0</pose>
          <mass>3.067</mass>
          <inertia>
            <ixx>0.0142175</ixx>
            <ixy>-1.28579e-05</ixy>
            <ixz>-2.31364e-05</ixz>
            <iyy>0.0144041</iyy>
            <iyz>1.93404e-05</iyz>
            <izz>0.0104533</izz>
          </inertia>
        </inertial>
        <collision name='link_1_collision'>
          <pose frame=''>0 0 0 0 -0 0</pose>
          <geometry>
            <mesh>
              <scale>1 1 1</scale>
              <uri>/home/udp/ros_qtc_plugin/src/abb_experimental/abb_irb120_support/meshes/irb120_3_58/collision/link_1.stl</uri>
            </mesh>
          </geometry>
          <surface>
            <contact>
              <ode/>
            </contact>
            <friction>
              <ode/>
              <torsional>
                <ode/>
              </torsional>
            </friction>
            <bounce/>
          </surface>
          <max_contacts>10</max_contacts>
        </collision>
        <visual name='link_1_visual'>
          <pose frame=''>0 0 0 0 -0 0</pose>
          <geometry>
            <mesh>
              <scale>1 1 1</scale>
              <uri>/home/udp/ros_qtc_plugin/src/abb_experimental/abb_irb120_support/meshes/irb120_3_58/visual/link_1.stl</uri>
            </mesh>
          </geometry>
          <material>
            <script>
              <name>Gazebo/Orange</name>
              <uri>file://media/materials/scripts/gazebo.material</uri>
            </script>
          </material>
        </visual>
        <gravity>0</gravity>
        <velocity_decay/>
        <self_collide>0</self_collide>
        <kinematic>0</kinematic>
      </link>
      <joint name='joint_1' type='revolute'>
        <child>link_1</child>
        <parent>base_link</parent>
        <axis>
          <xyz>0 0 1</xyz>
          <limit>
            <lower>-2.87979</lower>
            <upper>2.87979</upper>
            <effort>0</effort>
            <velocity>4.36332</velocity>
          </limit>
          <dynamics>
            <damping>0</damping>
            <friction>0</friction>
            <spring_reference>0</spring_reference>
            <spring_stiffness>0</spring_stiffness>
          </dynamics>
          <use_parent_model_frame>1</use_parent_model_frame>
        </axis>
      </joint>
      <link name='link_2'>
        <pose frame=''>0 0 0.29 0 -0 0</pose>
        <inertial>
          <pose frame=''>0.00078 -0.00212 0.10124 0 -0 0</pose>
          <mass>3.909</mass>
          <inertia>
            <ixx>0.0603111</ixx>
            <ixy>9.83431e-06</ixy>
            <ixz>5.72407e-05</ixz>
            <iyy>0.041569</iyy>
            <iyz>-0.00050497</iyz>
            <izz>0.0259548</izz>
          </inertia>
        </inertial>
        <collision name='link_2_collision'>
          <pose frame=''>0 0 0 0 -0 0</pose>
          <geometry>
            <mesh>
              <scale>1 1 1</scale>
              <uri>/home/udp/ros_qtc_plugin/src/abb_experimental/abb_irb120_support/meshes/irb120_3_58/collision/link_2.stl</uri>
            </mesh>
          </geometry>
          <surface>
            <contact>
              <ode/>
            </contact>
            <friction>
              <ode/>
              <torsional>
                <ode/>
              </torsional>
            </friction>
            <bounce/>
          </surface>
          <max_contacts>10</max_contacts>
        </collision>
        <visual name='link_2_visual'>
          <pose frame=''>0 0 0 0 -0 0</pose>
          <geometry>
            <mesh>
              <scale>1 1 1</scale>
              <uri>/home/udp/ros_qtc_plugin/src/abb_experimental/abb_irb120_support/meshes/irb120_3_58/visual/link_2.stl</uri>
            </mesh>
          </geometry>
          <material>
            <script>
              <name>Gazebo/Orange</name>
              <uri>file://media/materials/scripts/gazebo.material</uri>
            </script>
          </material>
        </visual>
        <gravity>0</gravity>
        <velocity_decay/>
        <self_collide>0</self_collide>
        <kinematic>0</kinematic>
      </link>
      <joint name='joint_2' type='revolute'>
        <child>link_2</child>
        <parent>link_1</parent>
        <axis>
          <xyz>0 1 0</xyz>
          <limit>
            <lower>-1.91986</lower>
            <upper>1.91986</upper>
            <effort>0</effort>
            <velocity>4.36332</velocity>
          </limit>
          <dynamics>
            <damping>0</damping>
            <friction>0</friction>
            <spring_reference>0</spring_reference>
            <spring_stiffness>0</spring_stiffness>
          </dynamics>
          <use_parent_model_frame>1</use_parent_model_frame>
        </axis>
      </joint>
      <link name='link_3'>
        <pose frame=''>0 0 0.56 0 -0 0</pose>
        <inertial>
          <pose frame=''>0.02281 0.00106 0.05791 0 -0 0</pose>
          <mass>2.944</mass>
          <inertia>
            <ixx>0.00835606</ixx>
            <ixy>-8.01545e-05</ixy>
            <ixz>0.00142884</ixz>
            <iyy>0.016713</iyy>
            <iyz>-0.000182227</iyz>
            <izz>0.0126984</izz>
          </inertia>
        </inertial>
        <collision name='link_3_collision'>
          <pose frame=''>0 0 0 0 -0 0</pose>
          <geometry>
            <mesh>
              <scale>1 1 1</scale>
              <uri>/home/udp/ros_qtc_plugin/src/abb_experimental/abb_irb120_support/meshes/irb120_3_58/collision/link_3.stl</uri>
            </mesh>
          </geometry>
          <surface>
            <contact>
              <ode/>
            </contact>
            <friction>
              <ode/>
              <torsional>
                <ode/>
              </torsional>
            </friction>
            <bounce/>
          </surface>
          <max_contacts>10</max_contacts>
        </collision>
        <visual name='link_3_visual'>
          <pose frame=''>0 0 0 0 -0 0</pose>
          <geometry>
            <mesh>
              <scale>1 1 1</scale>
              <uri>/home/udp/ros_qtc_plugin/src/abb_experimental/abb_irb120_support/meshes/irb120_3_58/visual/link_3.stl</uri>
            </mesh>
          </geometry>
          <material>
            <script>
              <name>Gazebo/Orange</name>
              <uri>file://media/materials/scripts/gazebo.material</uri>
            </script>
          </material>
        </visual>
        <gravity>0</gravity>
        <velocity_decay/>
        <self_collide>0</self_collide>
        <kinematic>0</kinematic>
      </link>
      <joint name='joint_3' type='revolute'>
        <child>link_3</child>
        <parent>link_2</parent>
        <axis>
          <xyz>0 1 0</xyz>
          <limit>
            <lower>-1.91986</lower>
            <upper>1.22173</upper>
            <effort>0</effort>
            <velocity>4.36332</velocity>
          </limit>
          <dynamics>
            <damping>0</damping>
            <friction>0</friction>
            <spring_reference>0</spring_reference>
            <spring_stiffness>0</spring_stiffness>
          </dynamics>
          <use_parent_model_frame>1</use_parent_model_frame>
        </axis>
      </joint>
      <link name='link_4'>
        <pose frame=''>0 0 0.63 0 -0 0</pose>
        <inertial>
          <pose frame=''>0.2247 0.00015 0.00041 0 -0 0</pose>
          <mass>1.328</mass>
          <inertia>
            <ixx>0.00284661</ixx>
            <ixy>-2.12765e-05</ixy>
            <ixz>-1.6435e-05</ixz>
            <iyy>0.00401346</iyy>
            <iyz>1.31336e-05</iyz>
            <izz>0.0052535</izz>
          </inertia>
        </inertial>
        <collision name='link_4_collision'>
          <pose frame=''>0 0 0 0 -0 0</pose>
          <geometry>
            <mesh>
              <scale>1 1 1</scale>
              <uri>/home/udp/ros_qtc_plugin/src/abb_experimental/abb_irb120_support/meshes/irb120_3_58/collision/link_4.stl</uri>
            </mesh>
          </geometry>
          <surface>
            <contact>
              <ode/>
            </contact>
            <friction>
              <ode/>
              <torsional>
                <ode/>
              </torsional>
            </friction>
            <bounce/>
          </surface>
          <max_contacts>10</max_contacts>
        </collision>
        <visual name='link_4_visual'>
          <pose frame=''>0 0 0 0 -0 0</pose>
          <geometry>
            <mesh>
              <scale>1 1 1</scale>
              <uri>/home/udp/ros_qtc_plugin/src/abb_experimental/abb_irb120_support/meshes/irb120_3_58/visual/link_4.stl</uri>
            </mesh>
          </geometry>
          <material>
            <script>
              <name>Gazebo/Orange</name>
              <uri>file://media/materials/scripts/gazebo.material</uri>
            </script>
          </material>
        </visual>
        <gravity>0</gravity>
        <velocity_decay/>
        <self_collide>0</self_collide>
        <kinematic>0</kinematic>
      </link>
      <joint name='joint_4' type='revolute'>
        <child>link_4</child>
        <parent>link_3</parent>
        <axis>
          <xyz>1 0 0</xyz>
          <limit>
            <lower>-2.79253</lower>
            <upper>2.79253</upper>
            <effort>0</effort>
            <velocity>5.58505</velocity>
          </limit>
          <dynamics>
            <damping>0</damping>
            <friction>0</friction>
            <spring_reference>0</spring_reference>
            <spring_stiffness>0</spring_stiffness>
          </dynamics>
          <use_parent_model_frame>1</use_parent_model_frame>
        </axis>
      </joint>
      <link name='link_5'>
        <pose frame=''>0.302 0 0.63 0 -0 0</pose>
        <inertial>
          <pose frame=''>-0.00109 3.7e-05 6.2e-05 0 -0 0</pose>
          <mass>0.546</mass>
          <inertia>
            <ixx>0.000404891</ixx>
            <ixy>1.61943e-06</ixy>
            <ixz>8.46805e-07</ixz>
            <iyy>0.000892825</iyy>
            <iyz>-1.51792e-08</iyz>
            <izz>0.000815468</izz>
          </inertia>
        </inertial>
        <collision name='link_5_collision'>
          <pose frame=''>0 0 0 0 -0 0</pose>
          <geometry>
            <mesh>
              <scale>1 1 1</scale>
              <uri>/home/udp/ros_qtc_plugin/src/abb_experimental/abb_irb120_support/meshes/irb120_3_58/collision/link_5.stl</uri>
            </mesh>
          </geometry>
          <surface>
            <contact>
              <ode/>
            </contact>
            <friction>
              <ode/>
              <torsional>
                <ode/>
              </torsional>
            </friction>
            <bounce/>
          </surface>
          <max_contacts>10</max_contacts>
        </collision>
        <visual name='link_5_visual'>
          <pose frame=''>0 0 0 0 -0 0</pose>
          <geometry>
            <mesh>
              <scale>1 1 1</scale>
              <uri>/home/udp/ros_qtc_plugin/src/abb_experimental/abb_irb120_support/meshes/irb120_3_58/visual/link_5.stl</uri>
            </mesh>
          </geometry>
          <material>
            <script>
              <name>Gazebo/Orange</name>
              <uri>file://media/materials/scripts/gazebo.material</uri>model
            </script>
          </material>
        </visual>
        <gravity>0</gravity>
        <velocity_decay/>
        <self_collide>0</self_collide>
        <kinematic>0</kinematic>
      </link>
      <joint name='joint_5' type='revolute'>
        <child>link_5</child>
        <parent>link_4</parent>model
        <axis>
          <xyz>0 1 0</xyz>
          <limit>
            <lower>-2.0944</lower>
            <upper>2.0944</upper>
            <effort>0</effort>
            <velocity>5.58505</velocity>
          </limit>
          <dynamics>
            <damping>0</damping>
            <friction>0</friction>
            <spring_reference>0</spring_reference>
            <spring_stiffness>0</spring_stiffness>
          </dynamics>
          <use_parent_model_frame>1</use_parent_model_frame>
        </axis>
      </joint>
      <link name='link_6'>
        <pose frame=''>0.374 0 0.63 0 -0 0</pose>
        <inertial>
          <pose frame=''>-0.00706 -0.00017 -1e-06 0 -0 0</pose>
          <mass>0.137</mass>
          <inertia>
            <ixx>0.001</ixx>
            <ixy>0</ixy>
            <ixz>0</ixz>
            <iyy>0.001</iyy>
            <iyz>0</iyz>
            <izz>0.001</izz>
          </inertia>
        </inertial>
        <collision name='link_6_collision'>
          <pose frame=''>0 0 0 0 -0 0</pose>
          <geometry>
            <mesh>
              <scale>1 1 1</scale>
              <uri>/home/udp/ros_qtc_plugin/src/abb_experimental/abb_irb120_support/meshes/irb120_3_58/collision/link_6.stl</uri>
            </mesh>
          </geometry>
          <surface>
            <contact>
              <ode/>
            </contact>
            <friction>
              <ode/>
              <torsional>
                <ode/>
              </torsional>
            </friction>
            <bounce/>
          </surface>
          <max_contacts>10</max_contacts>
        </collision>
        <visual name='link_6_visual'>
          <pose frame=''>0 0 0 0 -0 0</pose>
          <geometry>
            <mesh>
              <scale>1 1 1</scale>
              <uri>/home/udp/ros_qtc_plugin/src/abb_experimental/abb_irb120_support/meshes/irb120_3_58/visual/link_6.stl</uri>
            </mesh>
          </geometry>
          <material>
            <script>
              <name>Gazebo/Black</name>
              <uri>file://media/materials/scripts/gazebo.material</uri>
            </script>
          </material>
        </visual>
        <gravity>0</gravity>
        <velocity_decay/>
        <self_collide>0</self_collide>
        <kinematic>0</kinematic>
      </link>
      <joint name='joint_6' type='revolute'>
        <child>link_6</child>
        <parent>link_5</parent>
        <axis>
          <xyz>1 0 0</xyz>
          <limit>
            <lower>-6.98132</lower>
            <upper>6.98132</upper>
            <effort>0</effort>
            <velocity>7.33038</velocity>
          </limit>
          <dynamics>
            <damping>0</damping>
            <friction>0</friction>
            <spring_reference>0</spring_reference>
            <spring_stiffness>0</spring_stiffness>
          </dynamics>
          <use_parent_model_frame>1</use_parent_model_frame>
        </axis>
      </joint>
      <static>0</static>
    <!--  <plugin name='gazebo_ros_control' filename='libgazebo_ros_control.so'>
        <robotNamespace>/</robotNamespace>
        <robotSimType>gazebo_ros_control/DefaultRobotHWSim</robotSimType>
      </plugin>-->
      <pose frame=''>0 0 0 0 -0 0</pose>
         <plugin name="actuador" filename="libmirobot.so">
     </plugin>
    </model>
    <state world_name='default'>
      <sim_time>30 477000000</sim_time>
      <real_time>39 278407423</real_time>
      <wall_time>1497686985 55728096</wall_time>
      <iterations>30477</iterations>
      <model name='abb_irb120_3_58'>
        <pose frame=''>0 0 0 0 -0 0</pose>
        <scale>1 1 1</scale>
        <link name='base_link'>
          <pose frame=''>0 0 0 0 -0 0</pose>
          <velocity>0 0 0 0 -0 0</velocity>
          <acceleration>0 0 0 0 -0 0</acceleration>
          <wrench>0 0 0 0 -0 0</wrench>
        </link>
        <link name='link_1'>
          <pose frame=''>0 0 0 0 -0 0</pose>
          <velocity>0 0 0 0 -0 0</velocity>
          <acceleration>0 0 0 0 -0 0</acceleration>
          <wrench>0 0 0 0 -0 0</wrench>
        </link>
        <link name='link_2'>
          <pose frame=''>0 0 0.29 0 -0 0</pose>
          <velocity>0 0 0 0 -0 0</velocity>
          <acceleration>0 0 0 0 -0 0</acceleration>
          <wrench>0 0 0 0 -0 0</wrench>
        </link>
        <link name='link_3'>
          <pose frame=''>0 0 0.56 0 -0 0</pose>
          <velocity>0 0 0 0 -0 0</velocity>
          <acceleration>0 0 0 0 -0 0</acceleration>
          <wrench>0 0 0 0 -0 0</wrench>
        </link>
        <link name='link_4'>
          <pose frame=''>0 0 0.63 0 -0 0</pose>
          <velocity>0 0 0 0 -0 0</velocity>
          <acceleration>0 0 0 0 -0 0</acceleration>
          <wrench>0 0 0 0 -0 0</wrench>
        </link>
        <link name='link_5'>
          <pose frame=''>0.302 0 0.63 0 -0 0</pose>
          <velocity>0 0 0 0 -0 0</velocity>
          <acceleration>0 0 0 0 -0 0</acceleration>
          <wrench>0 0 0 0 -0 0</wrench>
        </link>
        <link name='link_6'>
          <pose frame=''>0.374 0 0.63 0 -0 0</pose>
          <velocity>0 0 0 0 -0 0</velocity>
          <acceleration>0 0 0 0 -0 0</acceleration>
          <wrench>0 0 0 0 -0 0</wrench>
        </link>
      </model>
      <model name='ground_plane'>
        <pose frame=''>0 0 0 0 -0 0</pose>
        <scale>1 1 1</scale>
        <link name='link'>
          <pose frame=''>0 0 0 0 -0 0</pose>
          <velocity>0 0 0 0 -0 0</velocity>
          <acceleration>0 0 0 0 -0 0</acceleration>
          <wrench>0 0 0 0 -0 0</wrench>
        </link>
      </model>
      <light name='sun'>
        <pose frame=''>0 0 10 0 -0 0</pose>
      </light>
    </state>
    <gui fullscreen='0'>
      <camera name='user_camera'>
        <pose frame=''>3.00349 -2.9653 1.26671 0 0.275643 2.35619</pose>
        <view_controller>orbit</view_controller>
        <projection_type>perspective</projection_type>
      </camera>
    </gui>
  </world>
</sdf>
